Workbook

Sheet Resumen
A1: Estados financieros - Berts Solutions SL
A2: Generado el 22/09/2026 con scripts/generar_informes.py a partir de /datos/. No se edita a mano: se vuelve a generar con cada actualización.
B4: Fecha de corte del balance | C4: 46287 | D4: Puedes poner una fecha ANTERIOR para ver el balance a ese día. Para una fecha posterior, vuelve a generar el informe (la amortización se calcula hasta la fecha de generación).
B5: Fecha comparativa (último cierre) | C5: 46022
B7: Cifras clave a la fecha de corte | C7: Importe (€) | D7: Qué significa
B8: Total activo (lo que tiene la empresa) | C8: =Balance!D21 -> 92959.82 | D8: Vehículos (neto de amortización) + dinero + lo que le deben.
B9: Tesorería según contabilidad | C9: =Balance!D20 -> 52415.82 | D9: Debería coincidir con el extracto del BBVA. Sin extractos no está comprobado.
B10: Vehículos (valor neto contable) | C10: =Balance!D7 -> 32340.84 | D10: Coste de los vehículos menos la amortización acumulada.
B11: Clientes pendientes de cobro | C11: =Balance!D15 -> 4890.85 | D11: Facturas emitidas que no nos consta que se hayan cobrado.
B12: Patrimonio neto (lo que es de los socios) | C12: =Balance!D24 -> 67535.82 | D12: Capital + aportaciones + resultados acumulados.
B13: Partidas pendientes de aplicación (cuenta 555) | C13: =Balance!D36 -> 24498.06 | D13: Pagos cuyo origen desconocemos. Tiene que llegar a 0 cuando tengamos los extractos.
B14: Ingresos por alquiler del ejercicio | C14: =PyG!H8 -> 1737.73 | D14: Cifra de negocios acumulada.
B15: Resultado del ejercicio (beneficio / pérdida) | C15: =PyG!H26 -> -7782.79 | D15: Ingresos menos todos los gastos, incluida la amortización y la pérdida del Ford Fiesta.
B17: Controles de cuadre | C17: Diferencia (€) | D17: Estado
B18: Activo = Patrimonio neto + Pasivo | C18: =Balance!D21-Balance!D41 -> 0 | D18: =IF(ABS(C18)<0.01,"OK","ERROR - revisar") -> OK
B19: Libro diario: Debe = Haber | C19: =Diario!F231-Diario!G231 -> 0 | D19: =IF(ABS(C19)<0.01,"OK","ERROR - revisar") -> OK
B20: Resultado de la PyG = Resultado del balance | C20: =PyG!H26-Balance!D29 -> 0 | D20: =IF(ABS(C20)<0.01,"OK","ERROR - revisar") -> OK
B21: Balance 31/12/2025 = el de Fisama (75.318,61 €) | C21: =Balance!C21-75318.61 -> 0 | D21: =IF(ABS(C21)<0.01,"OK","ERROR - revisar") -> OK
B23: Hojas de este libro
B24: Balance | D24: Balance de situación (modelo PGC Pymes) a 31/12/2025 y a la fecha de corte.
B25: PyG | D25: Cuenta de pérdidas y ganancias por trimestres + detalle por cuenta.
B26: Vehículos | D26: Coste, amortización, valor neto y resultado de cada vehículo.
B27: IVA | D27: IVA repercutido y soportado por trimestre, para contrastar con el modelo 303.
B28: Pendiente | D28: 19 avisos: información que falta o no cuadra.
B29: Diario | D29: Libro diario: todos los asientos. Todo lo demás sale de aquí.
B30: Sumas y saldos | D30: Saldo de cada cuenta contable.
B31: Plan de cuentas | D31: Qué cuenta va a qué línea del balance y de la PyG.
B33: Leyenda de colores
B34: Azul: dato introducido (fecha de corte, cifras de Fisama, precios de compra).
B35: Negro: fórmula calculada a partir del Diario.
B36: Verde: enlace a otra hoja de este libro.
B37: Fondo amarillo: celda que puedes cambiar.

Sheet Balance
A1: Balance de Situación - Berts Solutions SL (CIF B23928419)
A2: Modelo PGC Pymes. Todas las cifras salen del Diario con fórmulas. La columna del 31/12/2025 reproduce el balance presentado por Fisama.
B4: ACTIVO | C4: =FechaComparativa -> 46022 | D4: =FechaCorte -> 46287
A5: A | B5: A) ACTIVO NO CORRIENTE | C5: =C6+C7+C11 -> 9192 | D5: =D6+D7+D11 -> 32340.84
A6: AI | B6: I. Inmovilizado intangible | C6: =SUMIFS(Diario!$K$2:$K$229,Diario!$L$2:$L$229,"AI",Diario!$B$2:$B$229,"<="&C$4) -> 0 | D6: =SUMIFS(Diario!$K$2:$K$229,Diario!$L$2:$L$229,"AI",Diario!$B$2:$B$229,"<="&D$4) -> 0
A7: AII | B7: II. Inmovilizado material | C7: =C8+C9+C10 -> 9192 | D7: =D8+D9+D10 -> 32340.84
A8: AII1 | B8: Elementos de transporte (vehículos) | C8: =SUMIFS(Diario!$K$2:$K$229,Diario!$L$2:$L$229,"AII1",Diario!$B$2:$B$229,"<="&C$4) -> 0 | D8: =SUMIFS(Diario!$K$2:$K$229,Diario!$L$2:$L$229,"AII1",Diario!$B$2:$B$229,"<="&D$4) -> 33790.93
A9: AII2 | B9: Otro inmovilizado material | C9: =SUMIFS(Diario!$K$2:$K$229,Diario!$L$2:$L$229,"AII2",Diario!$B$2:$B$229,"<="&C$4) -> 9192 | D9: =SUMIFS(Diario!$K$2:$K$229,Diario!$L$2:$L$229,"AII2",Diario!$B$2:$B$229,"<="&D$4) -> 0
A10: AII3 | B10: Amortización acumulada | C10: =SUMIFS(Diario!$K$2:$K$229,Diario!$L$2:$L$229,"AII3",Diario!$B$2:$B$229,"<="&C$4) -> 0 | D10: =SUMIFS(Diario!$K$2:$K$229,Diario!$L$2:$L$229,"AII3",Diario!$B$2:$B$229,"<="&D$4) -> -1450.09
A11: AV | B11: V. Inversiones financieras a largo plazo | C11: =SUMIFS(Diario!$K$2:$K$229,Diario!$L$2:$L$229,"AV",Diario!$B$2:$B$229,"<="&C$4) -> 0 | D11: =SUMIFS(Diario!$K$2:$K$229,Diario!$L$2:$L$229,"AV",Diario!$B$2:$B$229,"<="&D$4) -> 0
A12: B | B12: B) ACTIVO CORRIENTE | C12: =C13+C14+C19+C20 -> 66126.61 | D12: =D13+D14+D19+D20 -> 60618.98
A13: BII | B13: II. Existencias | C13: =SUMIFS(Diario!$K$2:$K$229,Diario!$L$2:$L$229,"BII",Diario!$B$2:$B$229,"<="&C$4) -> 0 | D13: =SUMIFS(Diario!$K$2:$K$229,Diario!$L$2:$L$229,"BII",Diario!$B$2:$B$229,"<="&D$4) -> 0
A14: BIII | B14: III. Deudores comerciales y otras cuentas a cobrar | C14: =C15+C16+C17+C18 -> 0 | D14: =D15+D16+D17+D18 -> 8203.16
A15: BIII1 | B15: 1. Clientes por ventas y prestaciones de servicios | C15: =SUMIFS(Diario!$K$2:$K$229,Diario!$L$2:$L$229,"BIII1",Diario!$B$2:$B$229,"<="&C$4) -> 0 | D15: =SUMIFS(Diario!$K$2:$K$229,Diario!$L$2:$L$229,"BIII1",Diario!$B$2:$B$229,"<="&D$4) -> 4890.85
A16: BIII2 | B16: 2. Hacienda Pública deudora (IVA soportado / a compensar) | C16: =SUMIFS(Diario!$K$2:$K$229,Diario!$L$2:$L$229,"BIII2",Diario!$B$2:$B$229,"<="&C$4) -> 0 | D16: =SUMIFS(Diario!$K$2:$K$229,Diario!$L$2:$L$229,"BIII2",Diario!$B$2:$B$229,"<="&D$4) -> 3312.31
A17: BIII3 | B17: 3. Socios deudores | C17: =MAX(0,SUMIFS(Diario!$K$2:$K$229,Diario!$L$2:$L$229,"D551",Diario!$B$2:$B$229,"<="&C$4)) -> 0 | D17: =MAX(0,SUMIFS(Diario!$K$2:$K$229,Diario!$L$2:$L$229,"D551",Diario!$B$2:$B$229,"<="&D$4)) -> 0
A18: BIII4 | B18: 4. Partidas pendientes de aplicación (saldo deudor) | C18: =MAX(0,SUMIFS(Diario!$K$2:$K$229,Diario!$L$2:$L$229,"D555",Diario!$B$2:$B$229,"<="&C$4)) -> 0 | D18: =MAX(0,SUMIFS(Diario!$K$2:$K$229,Diario!$L$2:$L$229,"D555",Diario!$B$2:$B$229,"<="&D$4)) -> 0
A19: BVI | B19: VI. Periodificaciones a corto plazo | C19: =SUMIFS(Diario!$K$2:$K$229,Diario!$L$2:$L$229,"BVI",Diario!$B$2:$B$229,"<="&C$4) -> 0 | D19: =SUMIFS(Diario!$K$2:$K$229,Diario!$L$2:$L$229,"BVI",Diario!$B$2:$B$229,"<="&D$4) -> 0
A20: BVII | B20: VII. Efectivo y otros activos líquidos equivalentes | C20: =SUMIFS(Diario!$K$2:$K$229,Diario!$L$2:$L$229,"BVII",Diario!$B$2:$B$229,"<="&C$4) -> 66126.61 | D20: =SUMIFS(Diario!$K$2:$K$229,Diario!$L$2:$L$229,"BVII",Diario!$B$2:$B$229,"<="&D$4) -> 52415.82
A21: TA | B21: TOTAL ACTIVO (A + B) | C21: =C5+C12 -> 75318.61 | D21: =D5+D12 -> 92959.82
B23: PATRIMONIO NETO Y PASIVO | C23: =FechaComparativa -> 46022 | D23: =FechaCorte -> 46287
A24: PA | B24: A) PATRIMONIO NETO | C24: =C25+C26+C27+C28+C29 -> 75318.61 | D24: =D25+D26+D27+D28+D29 -> 67535.82
A25: PAI | B25: I. Capital | C25: =-SUMIFS(Diario!$K$2:$K$229,Diario!$L$2:$L$229,"PAI",Diario!$B$2:$B$229,"<="&C$4) -> 3100 | D25: =-SUMIFS(Diario!$K$2:$K$229,Diario!$L$2:$L$229,"PAI",Diario!$B$2:$B$229,"<="&D$4) -> 3100
A26: PAIII | B26: III. Reservas | C26: =-SUMIFS(Diario!$K$2:$K$229,Diario!$L$2:$L$229,"PAIII",Diario!$B$2:$B$229,"<="&C$4) -> 0 | D26: =-SUMIFS(Diario!$K$2:$K$229,Diario!$L$2:$L$229,"PAIII",Diario!$B$2:$B$229,"<="&D$4) -> 6.49
A27: PAV | B27: V. Resultados de ejercicios anteriores | C27: =-SUMIFS(Diario!$K$2:$K$229,Diario!$L$2:$L$229,"PAV",Diario!$B$2:$B$229,"<="&C$4) -> 0 | D27: =-SUMIFS(Diario!$K$2:$K$229,Diario!$L$2:$L$229,"PAV",Diario!$B$2:$B$229,"<="&D$4) -> 58.39
A28: PAVI | B28: VI. Otras aportaciones de socios | C28: =-SUMIFS(Diario!$K$2:$K$229,Diario!$L$2:$L$229,"PAVI",Diario!$B$2:$B$229,"<="&C$4) -> 72153.73 | D28: =-SUMIFS(Diario!$K$2:$K$229,Diario!$L$2:$L$229,"PAVI",Diario!$B$2:$B$229,"<="&D$4) -> 72153.73
A29: PAVII | B29: VII. Resultado del ejercicio | C29: =-SUMIFS(Diario!$K$2:$K$229,Diario!$L$2:$L$229,"PAVII",Diario!$B$2:$B$229,"<="&C$4) -> 64.88 | D29: =-SUMIFS(Diario!$K$2:$K$229,Diario!$L$2:$L$229,"PAVII",Diario!$B$2:$B$229,"<="&D$4) -> -7782.79
A30: PB | B30: B) PASIVO NO CORRIENTE | C30: =C31 -> 0 | D30: =D31 -> 0
A31: PBII | B31: II. Deudas a largo plazo (bancos, préstamos de socios) | C31: =-SUMIFS(Diario!$K$2:$K$229,Diario!$L$2:$L$229,"PBII",Diario!$B$2:$B$229,"<="&C$4) -> 0 | D31: =-SUMIFS(Diario!$K$2:$K$229,Diario!$L$2:$L$229,"PBII",Diario!$B$2:$B$229,"<="&D$4) -> 0
A32: PC | B32: C) PASIVO CORRIENTE | C32: =C33+C37 -> 0 | D32: =D33+D37 -> 25424
A33: PCIII | B33: III. Deudas a corto plazo | C33: =C34+C35+C36 -> 0 | D33: =D34+D35+D36 -> 24498.06
A34: PCIII1 | B34: 1. Deudas con entidades de crédito | C34: =-SUMIFS(Diario!$K$2:$K$229,Diario!$L$2:$L$229,"PCIII1",Diario!$B$2:$B$229,"<="&C$4) -> 0 | D34: =-SUMIFS(Diario!$K$2:$K$229,Diario!$L$2:$L$229,"PCIII1",Diario!$B$2:$B$229,"<="&D$4) -> 0
A35: PCIII2 | B35: 2. Deudas con socios | C35: =MAX(0,-SUMIFS(Diario!$K$2:$K$229,Diario!$L$2:$L$229,"D551",Diario!$B$2:$B$229,"<="&C$4)) -> 0 | D35: =MAX(0,-SUMIFS(Diario!$K$2:$K$229,Diario!$L$2:$L$229,"D551",Diario!$B$2:$B$229,"<="&D$4)) -> 0
A36: PCIII3 | B36: 3. Partidas pendientes de aplicación (saldo acreedor) | C36: =MAX(0,-SUMIFS(Diario!$K$2:$K$229,Diario!$L$2:$L$229,"D555",Diario!$B$2:$B$229,"<="&C$4)) -> 0 | D36: =MAX(0,-SUMIFS(Diario!$K$2:$K$229,Diario!$L$2:$L$229,"D555",Diario!$B$2:$B$229,"<="&D$4)) -> 24498.06
A37: PCV | B37: V. Acreedores comerciales y otras cuentas a pagar | C37: =C38+C39+C40 -> 0 | D37: =D38+D39+D40 -> 925.94
A38: PCV1 | B38: 1. Proveedores y acreedores | C38: =-SUMIFS(Diario!$K$2:$K$229,Diario!$L$2:$L$229,"PCV1",Diario!$B$2:$B$229,"<="&C$4) -> 0 | D38: =-SUMIFS(Diario!$K$2:$K$229,Diario!$L$2:$L$229,"PCV1",Diario!$B$2:$B$229,"<="&D$4) -> 640.95
A39: PCV2 | B39: 2. Hacienda Pública acreedora (IVA, retenciones, Sociedades) | C39: =-SUMIFS(Diario!$K$2:$K$229,Diario!$L$2:$L$229,"PCV2",Diario!$B$2:$B$229,"<="&C$4) -> 0 | D39: =-SUMIFS(Diario!$K$2:$K$229,Diario!$L$2:$L$229,"PCV2",Diario!$B$2:$B$229,"<="&D$4) -> 284.99
A40: PCV3 | B40: 3. Seguridad Social y personal | C40: =-SUMIFS(Diario!$K$2:$K$229,Diario!$L$2:$L$229,"PCV3",Diario!$B$2:$B$229,"<="&C$4) -> 0 | D40: =-SUMIFS(Diario!$K$2:$K$229,Diario!$L$2:$L$229,"PCV3",Diario!$B$2:$B$229,"<="&D$4) -> 0
A41: TP | B41: TOTAL PATRIMONIO NETO Y PASIVO (A + B + C) | C41: =C24+C30+C32 -> 75318.61 | D41: =D24+D30+D32 -> 92959.82
B43: Comprobación: Activo − (Patrimonio neto + Pasivo) | C43: =C21-C41 -> 0 | D43: =D21-D41 -> 0
...

Sheet PyG
A1: Cuenta de Pérdidas y Ganancias - Berts Solutions SL
A2: Modelo PGC Pymes. Ingresos en positivo, gastos entre paréntesis. Trimestres del año de la fecha de corte.
C4: 2025 (Fisama) | D4: ="T1 "&YEAR(FechaCorte) -> T1 2026 | E4: ="T2 "&YEAR(FechaCorte) -> T2 2026 | F4: ="T3 "&YEAR(FechaCorte) -> T3 2026 | G4: ="T4 "&YEAR(FechaCorte) -> T4 2026 | H4: Acumulado a fecha de corte
B5: Desde | C5: 01/01/2025 | D5: =DATE(YEAR(FechaCorte),1,1) -> 46023 | E5: =DATE(YEAR(FechaCorte),4,1) -> 46113 | F5: =DATE(YEAR(FechaCorte),7,1) -> 46204 | G5: =DATE(YEAR(FechaCorte),10,1) -> 46296 | H5: =DATE(YEAR(FechaCorte),1,1) -> 46023
B6: Hasta | C6: 31/12/2025 | D6: =MIN(DATE(YEAR(FechaCorte),4,1)-1,FechaCorte) -> 46112 | E6: =MIN(DATE(YEAR(FechaCorte),7,1)-1,FechaCorte) -> 46203 | F6: =MIN(DATE(YEAR(FechaCorte),10,1)-1,FechaCorte) -> 46287 | G6: =MIN(DATE(YEAR(FechaCorte),13,1)-1,FechaCorte) -> 46287 | H6: =FechaCorte -> 46287
A8: P1 | B8: 1. Importe neto de la cifra de negocios | C8: 2574.25 | D8: =-SUMIFS(Diario!$K$2:$K$229,Diario!$M$2:$M$229,"P1",Diario!$B$2:$B$229,">="&D$5,Diario!$B$2:$B$229,"<="&D$6,Diario!$H$2:$H$229,"<>REG") -> 0 | E8: =-SUMIFS(Diario!$K$2:$K$229,Diario!$M$2:$M$229,"P1",Diario!$B$2:$B$229,">="&E$5,Diario!$B$2:$B$229,"<="&E$6,Diario!$H$2:$H$229,"<>REG") -> 1737.73 | F8: =-SUMIFS(Diario!$K$2:$K$229,Diario!$M$2:$M$229,"P1",Diario!$B$2:$B$229,">="&F$5,Diario!$B$2:$B$229,"<="&F$6,Diario!$H$2:$H$229,"<>REG") -> 0 | G8: =-SUMIFS(Diario!$K$2:$K$229,Diario!$M$2:$M$229,"P1",Diario!$B$2:$B$229,">="&G$5,Diario!$B$2:$B$229,"<="&G$6,Diario!$H$2:$H$229,"<>REG") -> 0 | H8: =-SUMIFS(Diario!$K$2:$K$229,Diario!$M$2:$M$229,"P1",Diario!$B$2:$B$229,">="&H$5,Diario!$B$2:$B$229,"<="&H$6,Diario!$H$2:$H$229,"<>REG") -> 1737.73
A9: P4 | B9: 4. Aprovisionamientos | C9: 0 | D9: =-SUMIFS(Diario!$K$2:$K$229,Diario!$M$2:$M$229,"P4",Diario!$B$2:$B$229,">="&D$5,Diario!$B$2:$B$229,"<="&D$6,Diario!$H$2:$H$229,"<>REG") -> 0 | E9: =-SUMIFS(Diario!$K$2:$K$229,Diario!$M$2:$M$229,"P4",Diario!$B$2:$B$229,">="&E$5,Diario!$B$2:$B$229,"<="&E$6,Diario!$H$2:$H$229,"<>REG") -> 0 | F9: =-SUMIFS(Diario!$K$2:$K$229,Diario!$M$2:$M$229,"P4",Diario!$B$2:$B$229,">="&F$5,Diario!$B$2:$B$229,"<="&F$6,Diario!$H$2:$H$229,"<>REG") -> 0 | G9: =-SUMIFS(Diario!$K$2:$K$229,Diario!$M$2:$M$229,"P4",Diario!$B$2:$B$229,">="&G$5,Diario!$B$2:$B$229,"<="&G$6,Diario!$H$2:$H$229,"<>REG") -> 0 | H9: =-SUMIFS(Diario!$K$2:$K$229,Diario!$M$2:$M$229,"P4",Diario!$B$2:$B$229,">="&H$5,Diario!$B$2:$B$229,"<="&H$6,Diario!$H$2:$H$229,"<>REG") -> 0
A10: P5 | B10: 5. Otros ingresos de explotación | C10: 0 | D10: =-SUMIFS(Diario!$K$2:$K$229,Diario!$M$2:$M$229,"P5",Diario!$B$2:$B$229,">="&D$5,Diario!$B$2:$B$229,"<="&D$6,Diario!$H$2:$H$229,"<>REG") -> 0 | E10: =-SUMIFS(Diario!$K$2:$K$229,Diario!$M$2:$M$229,"P5",Diario!$B$2:$B$229,">="&E$5,Diario!$B$2:$B$229,"<="&E$6,Diario!$H$2:$H$229,"<>REG") -> 0 | F10: =-SUMIFS(Diario!$K$2:$K$229,Diario!$M$2:$M$229,"P5",Diario!$B$2:$B$229,">="&F$5,Diario!$B$2:$B$229,"<="&F$6,Diario!$H$2:$H$229,"<>REG") -> 0 | G10: =-SUMIFS(Diario!$K$2:$K$229,Diario!$M$2:$M$229,"P5",Diario!$B$2:$B$229,">="&G$5,Diario!$B$2:$B$229,"<="&G$6,Diario!$H$2:$H$229,"<>REG") -> 0 | H10: =-SUMIFS(Diario!$K$2:$K$229,Diario!$M$2:$M$229,"P5",Diario!$B$2:$B$229,">="&H$5,Diario!$B$2:$B$229,"<="&H$6,Diario!$H$2:$H$229,"<>REG") -> 0
A11: P6 | B11: 6. Gastos de personal | C11: 0 | D11: =-SUMIFS(Diario!$K$2:$K$229,Diario!$M$2:$M$229,"P6",Diario!$B$2:$B$229,">="&D$5,Diario!$B$2:$B$229,"<="&D$6,Diario!$H$2:$H$229,"<>REG") -> 0 | E11: =-SUMIFS(Diario!$K$2:$K$229,Diario!$M$2:$M$229,"P6",Diario!$B$2:$B$229,">="&E$5,Diario!$B$2:$B$229,"<="&E$6,Diario!$H$2:$H$229,"<>REG") -> 0 | F11: =-SUMIFS(Diario!$K$2:$K$229,Diario!$M$2:$M$229,"P6",Diario!$B$2:$B$229,">="&F$5,Diario!$B$2:$B$229,"<="&F$6,Diario!$H$2:$H$229,"<>REG") -> 0 | G11: =-SUMIFS(Diario!$K$2:$K$229,Diario!$M$2:$M$229,"P6",Diario!$B$2:$B$229,">="&G$5,Diario!$B$2:$B$229,"<="&G$6,Diario!$H$2:$H$229,"<>REG") -> 0 | H11: =-SUMIFS(Diario!$K$2:$K$229,Diario!$M$2:$M$229,"P6",Diario!$B$2:$B$229,">="&H$5,Diario!$B$2:$B$229,"<="&H$6,Diario!$H$2:$H$229,"<>REG") -> 0
A12: P7 | B12: 7. Otros gastos de explotación | C12: =C13+C14+C15 -> -2509.37 | D12: =D13+D14+D15 -> -1605.21 | E12: =E13+E14+E15 -> -878.97 | F12: =F13+F14+F15 -> -1623.17 | G12: =G13+G14+G15 -> 0 | H12: =H13+H14+H15 -> -4107.35
A13: P7a | B13: a) Servicios exteriores | C13: -2509.37 | D13: =-SUMIFS(Diario!$K$2:$K$229,Diario!$M$2:$M$229,"P7a",Diario!$B$2:$B$229,">="&D$5,Diario!$B$2:$B$229,"<="&D$6,Diario!$H$2:$H$229,"<>REG") -> -1605.21 | E13: =-SUMIFS(Diario!$K$2:$K$229,Diario!$M$2:$M$229,"P7a",Diario!$B$2:$B$229,">="&E$5,Diario!$B$2:$B$229,"<="&E$6,Diario!$H$2:$H$229,"<>REG") -> -734.28 | F13: =-SUMIFS(Diario!$K$2:$K$229,Diario!$M$2:$M$229,"P7a",Diario!$B$2:$B$229,">="&F$5,Diario!$B$2:$B$229,"<="&F$6,Diario!$H$2:$H$229,"<>REG") -> -1623.17 | G13: =-SUMIFS(Diario!$K$2:$K$229,Diario!$M$2:$M$229,"P7a",Diario!$B$2:$B$229,">="&G$5,Diario!$B$2:$B$229,"<="&G$6,Diario!$H$2:$H$229,"<>REG") -> 0 | H13: =-SUMIFS(Diario!$K$2:$K$229,Diario!$M$2:$M$229,"P7a",Diario!$B$2:$B$229,">="&H$5,Diario!$B$2:$B$229,"<="&H$6,Diario!$H$2:$H$229,"<>REG") -> -3962.66
A14: P7b | B14: b) Tributos | C14: 0 | D14: =-SUMIFS(Diario!$K$2:$K$229,Diario!$M$2:$M$229,"P7b",Diario!$B$2:$B$229,">="&D$5,Diario!$B$2:$B$229,"<="&D$6,Diario!$H$2:$H$229,"<>REG") -> 0 | E14: =-SUMIFS(Diario!$K$2:$K$229,Diario!$M$2:$M$229,"P7b",Diario!$B$2:$B$229,">="&E$5,Diario!$B$2:$B$229,"<="&E$6,Diario!$H$2:$H$229,"<>REG") -> -144.69 | F14: =-SUMIFS(Diario!$K$2:$K$229,Diario!$M$2:$M$229,"P7b",Diario!$B$2:$B$229,">="&F$5,Diario!$B$2:$B$229,"<="&F$6,Diario!$H$2:$H$229,"<>REG") -> 0 | G14: =-SUMIFS(Diario!$K$2:$K$229,Diario!$M$2:$M$229,"P7b",Diario!$B$2:$B$229,">="&G$5,Diario!$B$2:$B$229,"<="&G$6,Diario!$H$2:$H$229,"<>REG") -> 0 | H14: =-SUMIFS(Diario!$K$2:$K$229,Diario!$M$2:$M$229,"P7b",Diario!$B$2:$B$229,">="&H$5,Diario!$B$2:$B$229,"<="&H$6,Diario!$H$2:$H$229,"<>REG") -> -144.69
A15: P7c | B15: c) Otros gastos de gestión corriente | C15: 0 | D15: =-SUMIFS(Diario!$K$2:$K$229,Diario!$M$2:$M$229,"P7c",Diario!$B$2:$B$229,">="&D$5,Diario!$B$2:$B$229,"<="&D$6,Diario!$H$2:$H$229,"<>REG") -> 0 | E15: =-SUMIFS(Diario!$K$2:$K$229,Diario!$M$2:$M$229,"P7c",Diario!$B$2:$B$229,">="&E$5,Diario!$B$2:$B$229,"<="&E$6,Diario!$H$2:$H$229,"<>REG") -> 0 | F15: =-SUMIFS(Diario!$K$2:$K$229,Diario!$M$2:$M$229,"P7c",Diario!$B$2:$B$229,">="&F$5,Diario!$B$2:$B$229,"<="&F$6,Diario!$H$2:$H$229,"<>REG") -> 0 | G15: =-SUMIFS(Diario!$K$2:$K$229,Diario!$M$2:$M$229,"P7c",Diario!$B$2:$B$229,">="&G$5,Diario!$B$2:$B$229,"<="&G$6,Diario!$H$2:$H$229,"<>REG") -> 0 | H15: =-SUMIFS(Diario!$K$2:$K$229,Diario!$M$2:$M$229,"P7c",Diario!$B$2:$B$229,">="&H$5,Diario!$B$2:$B$229,"<="&H$6,Diario!$H$2:$H$229,"<>REG") -> 0
A16: P8 | B16: 8. Amortización del inmovilizado | C16: 0 | D16: =-SUMIFS(Diario!$K$2:$K$229,Diario!$M$2:$M$229,"P8",Diario!$B$2:$B$229,">="&D$5,Diario!$B$2:$B$229,"<="&D$6,Diario!$H$2:$H$229,"<>REG") -> -498.57 | E16: =-SUMIFS(Diario!$K$2:$K$229,Diario!$M$2:$M$229,"P8",Diario!$B$2:$B$229,">="&E$5,Diario!$B$2:$B$229,"<="&E$6,Diario!$H$2:$H$229,"<>REG") -> -720.29 | F16: =-SUMIFS(Diario!$K$2:$K$229,Diario!$M$2:$M$229,"P8",Diario!$B$2:$B$229,">="&F$5,Diario!$B$2:$B$229,"<="&F$6,Diario!$H$2:$H$229,"<>REG") -> -493.01 | G16: =-SUMIFS(Diario!$K$2:$K$229,Diario!$M$2:$M$229,"P8",Diario!$B$2:$B$229,">="&G$5,Diario!$B$2:$B$229,"<="&G$6,Diario!$H$2:$H$229,"<>REG") -> 0 | H16: =-SUMIFS(Diario!$K$2:$K$229,Diario!$M$2:$M$229,"P8",Diario!$B$2:$B$229,">="&H$5,Diario!$B$2:$B$229,"<="&H$6,Diario!$H$2:$H$229,"<>REG") -> -1711.87
A17: P11 | B17: 11. Deterioro y resultado por enajenaciones del inmovilizado | C17: 0 | D17: =-SUMIFS(Diario!$K$2:$K$229,Diario!$M$2:$M$229,"P11",Diario!$B$2:$B$229,">="&D$5,Diario!$B$2:$B$229,"<="&D$6,Diario!$H$2:$H$229,"<>REG") -> 0 | E17: =-SUMIFS(Diario!$K$2:$K$229,Diario!$M$2:$M$229,"P11",Diario!$B$2:$B$229,">="&E$5,Diario!$B$2:$B$229,"<="&E$6,Diario!$H$2:$H$229,"<>REG") -> -3414.92 | F17: =-SUMIFS(Diario!$K$2:$K$229,Diario!$M$2:$M$229,"P11",Diario!$B$2:$B$229,">="&F$5,Diario!$B$2:$B$229,"<="&F$6,Diario!$H$2:$H$229,"<>REG") -> 0 | G17: =-SUMIFS(Diario!$K$2:$K$229,Diario!$M$2:$M$229,"P11",Diario!$B$2:$B$229,">="&G$5,Diario!$B$2:$B$229,"<="&G$6,Diario!$H$2:$H$229,"<>REG") -> 0 | H17: =-SUMIFS(Diario!$K$2:$K$229,Diario!$M$2:$M$229,"P11",Diario!$B$2:$B$229,">="&H$5,Diario!$B$2:$B$229,"<="&H$6,Diario!$H$2:$H$229,"<>REG") -> -3414.92
A18: P12 | B18: 12. Otros resultados | C18: 0 | D18: =-SUMIFS(Diario!$K$2:$K$229,Diario!$M$2:$M$229,"P12",Diario!$B$2:$B$229,">="&D$5,Diario!$B$2:$B$229,"<="&D$6,Diario!$H$2:$H$229,"<>REG") -> 0 | E18: =-SUMIFS(Diario!$K$2:$K$229,Diario!$M$2:$M$229,"P12",Diario!$B$2:$B$229,">="&E$5,Diario!$B$2:$B$229,"<="&E$6,Diario!$H$2:$H$229,"<>REG") -> 0 | F18: =-SUMIFS(Diario!$K$2:$K$229,Diario!$M$2:$M$229,"P12",Diario!$B$2:$B$229,">="&F$5,Diario!$B$2:$B$229,"<="&F$6,Diario!$H$2:$H$229,"<>REG") -> -286.38 | G18: =-SUMIFS(Diario!$K$2:$K$229,Diario!$M$2:$M$229,"P12",Diario!$B$2:$B$229,">="&G$5,Diario!$B$2:$B$229,"<="&G$6,Diario!$H$2:$H$229,"<>REG") -> 0 | H18: =-SUMIFS(Diario!$K$2:$K$229,Diario!$M$2:$M$229,"P12",Diario!$B$2:$B$229,">="&H$5,Diario!$B$2:$B$229,"<="&H$6,Diario!$H$2:$H$229,"<>REG") -> -286.38
A19: A1 | B19: A.1) RESULTADO DE EXPLOTACIÓN | C19: =C8+C9+C10+C11+C12+C16+C17+C18 -> 64.88 | D19: =D8+D9+D10+D11+D12+D16+D17+D18 -> -2103.78 | E19: =E8+E9+E10+E11+E12+E16+E17+E18 -> -3276.45 | F19: =F8+F9+F10+F11+F12+F16+F17+F18 -> -2402.56 | G19: =G8+G9+G10+G11+G12+G16+G17+G18 -> 0 | H19: =H8+H9+H10+H11+H12+H16+H17+H18 -> -7782.79
A20: P13 | B20: 13. Ingresos financieros | C20: 0 | D20: =-SUMIFS(Diario!$K$2:$K$229,Diario!$M$2:$M$229,"P13",Diario!$B$2:$B$229,">="&D$5,Diario!$B$2:$B$229,"<="&D$6,Diario!$H$2:$H$229,"<>REG") -> 0 | E20: =-SUMIFS(Diario!$K$2:$K$229,Diario!$M$2:$M$229,"P13",Diario!$B$2:$B$229,">="&E$5,Diario!$B$2:$B$229,"<="&E$6,Diario!$H$2:$H$229,"<>REG") -> 0 | F20: =-SUMIFS(Diario!$K$2:$K$229,Diario!$M$2:$M$229,"P13",Diario!$B$2:$B$229,">="&F$5,Diario!$B$2:$B$229,"<="&F$6,Diario!$H$2:$H$229,"<>REG") -> 0 | G20: =-SUMIFS(Diario!$K$2:$K$229,Diario!$M$2:$M$229,"P13",Diario!$B$2:$B$229,">="&G$5,Diario!$B$2:$B$229,"<="&G$6,Diario!$H$2:$H$229,"<>REG") -> 0 | H20: =-SUMIFS(Diario!$K$2:$K$229,Diario!$M$2:$M$229,"P13",Diario!$B$2:$B$229,">="&H$5,Diario!$B$2:$B$229,"<="&H$6,Diario!$H$2:$H$229,"<>REG") -> 0
A21: P14 | B21: 14. Gastos financieros | C21: 0 | D21: =-SUMIFS(Diario!$K$2:$K$229,Diario!$M$2:$M$229,"P14",Diario!$B$2:$B$229,">="&D$5,Diario!$B$2:$B$229,"<="&D$6,Diario!$H$2:$H$229,"<>REG") -> 0 | E21: =-SUMIFS(Diario!$K$2:$K$229,Diario!$M$2:$M$229,"P14",Diario!$B$2:$B$229,">="&E$5,Diario!$B$2:$B$229,"<="&E$6,Diario!$H$2:$H$229,"<>REG") -> 0 | F21: =-SUMIFS(Diario!$K$2:$K$229,Diario!$M$2:$M$229,"P14",Diario!$B$2:$B$229,">="&F$5,Diario!$B$2:$B$229,"<="&F$6,Diario!$H$2:$H$229,"<>REG") -> 0 | G21: =-SUMIFS(Diario!$K$2:$K$229,Diario!$M$2:$M$229,"P14",Diario!$B$2:$B$229,">="&G$5,Diario!$B$2:$B$229,"<="&G$6,Diario!$H$2:$H$229,"<>REG") -> 0 | H21: =-SUMIFS(Diario!$K$2:$K$229,Diario!$M$2:$M$229,"P14",Diario!$B$2:$B$229,">="&H$5,Diario!$B$2:$B$229,"<="&H$6,Diario!$H$2:$H$229,"<>REG") -> 0
A22: P16 | B22: 16. Diferencias de cambio | C22: 0 | D22: =-SUMIFS(Diario!$K$2:$K$229,Diario!$M$2:$M$229,"P16",Diario!$B$2:$B$229,">="&D$5,Diario!$B$2:$B$229,"<="&D$6,Diario!$H$2:$H$229,"<>REG") -> 0 | E22: =-SUMIFS(Diario!$K$2:$K$229,Diario!$M$2:$M$229,"P16",Diario!$B$2:$B$229,">="&E$5,Diario!$B$2:$B$229,"<="&E$6,Diario!$H$2:$H$229,"<>REG") -> 0 | F22: =-SUMIFS(Diario!$K$2:$K$229,Diario!$M$2:$M$229,"P16",Diario!$B$2:$B$229,">="&F$5,Diario!$B$2:$B$229,"<="&F$6,Diario!$H$2:$H$229,"<>REG") -> 0 | G22: =-SUMIFS(Diario!$K$2:$K$229,Diario!$M$2:$M$229,"P16",Diario!$B$2:$B$229,">="&G$5,Diario!$B$2:$B$229,"<="&G$6,Diario!$H$2:$H$229,"<>REG") -> 0 | H22: =-SUMIFS(Diario!$K$2:$K$229,Diario!$M$2:$M$229,"P16",Diario!$B$2:$B$229,">="&H$5,Diario!$B$2:$B$229,"<="&H$6,Diario!$H$2:$H$229,"<>REG") -> 0
A23: A2 | B23: A.2) RESULTADO FINANCIERO | C23: =C20+C21+C22 -> 0 | D23: =D20+D21+D22 -> 0 | E23: =E20+E21+E22 -> 0 | F23: =F20+F21+F22 -> 0 | G23: =G20+G21+G22 -> 0 | H23: =H20+H21+H22 -> 0
A24: A3 | B24: A.3) RESULTADO ANTES DE IMPUESTOS | C24: =C19+C23 -> 64.88 | D24: =D19+D23 -> -2103.78 | E24: =E19+E23 -> -3276.45 | F24: =F19+F23 -> -2402.56 | G24: =G19+G23 -> 0 | H24: =H19+H23 -> -7782.79
A25: P17 | B25: 17. Impuestos sobre beneficios | C25: 0 | D25: =-SUMIFS(Diario!$K$2:$K$229,Diario!$M$2:$M$229,"P17",Diario!$B$2:$B$229,">="&D$5,Diario!$B$2:$B$229,"<="&D$6,Diario!$H$2:$H$229,"<>REG") -> 0 | E25: =-SUMIFS(Diario!$K$2:$K$229,Diario!$M$2:$M$229,"P17",Diario!$B$2:$B$229,">="&E$5,Diario!$B$2:$B$229,"<="&E$6,Diario!$H$2:$H$229,"<>REG") -> 0 | F25: =-SUMIFS(Diario!$K$2:$K$229,Diario!$M$2:$M$229,"P17",Diario!$B$2:$B$229,">="&F$5,Diario!$B$2:$B$229,"<="&F$6,Diario!$H$2:$H$229,"<>REG") -> 0 | G25: =-SUMIFS(Diario!$K$2:$K$229,Diario!$M$2:$M$229,"P17",Diario!$B$2:$B$229,">="&G$5,Diario!$B$2:$B$229,"<="&G$6,Diario!$H$2:$H$229,"<>REG") -> 0 | H25: =-SUMIFS(Diario!$K$2:$K$229,Diario!$M$2:$M$229,"P17",Diario!$B$2:$B$229,">="&H$5,Diario!$B$2:$B$229,"<="&H$6,Diario!$H$2:$H$229,"<>REG") -> 0
A26: A4 | B26: A.4) RESULTADO DEL EJERCICIO | C26: =C24+C25 -> 64.88 | D26: =D24+D25 -> -2103.78 | E26: =E24+E25 -> -3276.45 | F26: =F24+F25 -> -2402.56 | G26: =G24+G25 -> 0 | H26: =H24+H25 -> -7782.79
A29: Cuenta | B29: Detalle por cuenta (ingresos y gastos) | D29: T1 | E29: T2 | F29: T3 | G29: T4 | H29: Acumulado
A30: 6220 | B30: Reparaciones y conservación | D30: =-SUMIFS(Diario!$K$2:$K$229,Diario!$C$2:$C$229,$A30,Diario!$B$2:$B$229,">="&D$5,Diario!$B$2:$B$229,"<="&D$6,Diario!$H$2:$H$229,"<>REG") -> -964.26 | E30: =-SUMIFS(Diario!$K$2:$K$229,Diario!$C$2:$C$229,$A30,Diario!$B$2:$B$229,">="&E$5,Diario!$B$2:$B$229,"<="&E$6,Diario!$H$2:$H$229,"<>REG") -> -351.9 | F30: =-SUMIFS(Diario!$K$2:$K$229,Diario!$C$2:$C$229,$A30,Diario!$B$2:$B$229,">="&F$5,Diario!$B$2:$B$229,"<="&F$6,Diario!$H$2:$H$229,"<>REG") -> -676.17 | G30: =-SUMIFS(Diario!$K$2:$K$229,Diario!$C$2:$C$229,$A30,Diario!$B$2:$B$229,">="&G$5,Diario!$B$2:$B$229,"<="&G$6,Diario!$H$2:$H$229,"<>REG") -> 0 | H30: =-SUMIFS(Diario!$K$2:$K$229,Diario!$C$2:$C$229,$A30,Diario!$B$2:$B$229,">="&H$5,Diario!$B$2:$B$229,"<="&H$6,Diario!$H$2:$H$229,"<>REG") -> -1992.33
A31: 6230 | B31: Servicios de profesionales independientes | D31: =-SUMIFS(Diario!$K$2:$K$229,Diario!$C$2:$C$229,$A31,Diario!$B$2:$B$229,">="&D$5,Diario!$B$2:$B$229,"<="&D$6,Diario!$H$2:$H$229,"<>REG") -> 0 | E31: =-SUMIFS(Diario!$K$2:$K$229,Diario!$C$2:$C$229,$A31,Diario!$B$2:$B$229,">="&E$5,Diario!$B$2:$B$229,"<="&E$6,Diario!$H$2:$H$229,"<>REG") -> -41.49 | F31: =-SUMIFS(Diario!$K$2:$K$229,Diario!$C$2:$C$229,$A31,Diario!$B$2:$B$229,">="&F$5,Diario!$B$2:$B$229,"<="&F$6,Diario!$H$2:$H$229,"<>REG") -> 0 | G31: =-SUMIFS(Diario!$K$2:$K$229,Diario!$C$2:$C$229,$A31,Diario!$B$2:$B$229,">="&G$5,Diario!$B$2:$B$229,"<="&G$6,Diario!$H$2:$H$229,"<>REG") -> 0 | H31: =-SUMIFS(Diario!$K$2:$K$229,Diario!$C$2:$C$229,$A31,Diario!$B$2:$B$229,">="&H$5,Diario!$B$2:$B$229,"<="&H$6,Diario!$H$2:$H$229,"<>REG") -> -41.49
A32: 6250 | B32: Primas de seguros | D32: =-SUMIFS(Diario!$K$2:$K$229,Diario!$C$2:$C$229,$A32,Diario!$B$2:$B$229,">="&D$5,Diario!$B$2:$B$229,"<="&D$6,Diario!$H$2:$H$229,"<>REG") -> -640.95 | E32: =-SUMIFS(Diario!$K$2:$K$229,Diario!$C$2:$C$229,$A32,Diario!$B$2:$B$229,">="&E$5,Diario!$B$2:$B$229,"<="&E$6,Diario!$H$2:$H$229,"<>REG") -> 0 | F32: =-SUMIFS(Diario!$K$2:$K$229,Diario!$C$2:$C$229,$A32,Diario!$B$2:$B$229,">="&F$5,Diario!$B$2:$B$229,"<="&F$6,Diario!$H$2:$H$229,"<>REG") -> 0 | G32: =-SUMIFS(Diario!$K$2:$K$229,Diario!$C$2:$C$229,$A32,Diario!$B$2:$B$229,">="&G$5,Diario!$B$2:$B$229,"<="&G$6,Diario!$H$2:$H$229,"<>REG") -> 0 | H32: =-SUMIFS(Diario!$K$2:$K$229,Diario!$C$2:$C$229,$A32,Diario!$B$2:$B$229,">="&H$5,Diario!$B$2:$B$229,"<="&H$6,Diario!$H$2:$H$229,"<>REG") -> -640.95
A33: 6280 | B33: Suministros (combustible, luz, teléfono...) | D33: =-SUMIFS(Diario!$K$2:$K$229,Diario!$C$2:$C$229,$A33,Diario!$B$2:$B$229,">="&D$5,Diario!$B$2:$B$229,"<="&D$6,Diario!$H$2:$H$229,"<>REG") -> 0 | E33: =-SUMIFS(Diario!$K$2:$K$229,Diario!$C$2:$C$229,$A33,Diario!$B$2:$B$229,">="&E$5,Diario!$B$2:$B$229,"<="&E$6,Diario!$H$2:$H$229,"<>REG") -> -106.53 | F33: =-SUMIFS(Diario!$K$2:$K$229,Diario!$C$2:$C$229,$A33,Diario!$B$2:$B$229,">="&F$5,Diario!$B$2:$B$229,"<="&F$6,Diario!$H$2:$H$229,"<>REG") -> 0 | G33: =-SUMIFS(Diario!$K$2:$K$229,Diario!$C$2:$C$229,$A33,Diario!$B$2:$B$229,">="&G$5,Diario!$B$2:$B$229,"<="&G$6,Diario!$H$2:$H$229,"<>REG") -> 0 | H33: =-SUMIFS(Diario!$K$2:$K$229,Diario!$C$2:$C$229,$A33,Diario!$B$2:$B$229,">="&H$5,Diario!$B$2:$B$229,"<="&H$6,Diario!$H$2:$H$229,"<>REG") -> -106.53
A34: 6290 | B34: Otros servicios | D34: =-SUMIFS(Diario!$K$2:$K$229,Diario!$C$2:$C$229,$A34,Diario!$B$2:$B$229,">="&D$5,Diario!$B$2:$B$229,"<="&D$6,Diario!$H$2:$H$229,"<>REG") -> 0 | E34: =-SUMIFS(Diario!$K$2:$K$229,Diario!$C$2:$C$229,$A34,Diario!$B$2:$B$229,">="&E$5,Diario!$B$2:$B$229,"<="&E$6,Diario!$H$2:$H$229,"<>REG") -> -234.36 | F34: =-SUMIFS(Diario!$K$2:$K$229,Diario!$C$2:$C$229,$A34,Diario!$B$2:$B$229,">="&F$5,Diario!$B$2:$B$229,"<="&F$6,Diario!$H$2:$H$229,"<>REG") -> -947 | G34: =-SUMIFS(Diario!$K$2:$K$229,Diario!$C$2:$C$229,$A34,Diario!$B$2:$B$229,">="&G$5,Diario!$B$2:$B$229,"<="&G$6,Diario!$H$2:$H$229,"<>REG") -> 0 | H34: =-SUMIFS(Diario!$K$2:$K$229,Diario!$C$2:$C$229,$A34,Diario!$B$2:$B$229,">="&H$5,Diario!$B$2:$B$229,"<="&H$6,Diario!$H$2:$H$229,"<>REG") -> -1181.36
A35: 6310 | B35: Otros tributos (IVTM...) | D35: =-SUMIFS(Diario!$K$2:$K$229,Diario!$C$2:$C$229,$A35,Diario!$B$2:$B$229,">="&D$5,Diario!$B$2:$B$229,"<="&D$6,Diario!$H$2:$H$229,"<>REG") -> 0 | E35: =-SUMIFS(Diario!$K$2:$K$229,Diario!$C$2:$C$229,$A35,Diario!$B$2:$B$229,">="&E$5,Diario!$B$2:$B$229,"<="&E$6,Diario!$H$2:$H$229,"<>REG") -> -144.69 | F35: =-SUMIFS(Diario!$K$2:$K$229,Diario!$C$2:$C$229,$A35,Diario!$B$2:$B$229,">="&F$5,Diario!$B$2:$B$229,"<="&F$6,Diario!$H$2:$H$229,"<>REG") -> 0 | G35: =-SUMIFS(Diario!$K$2:$K$229,Diario!$C$2:$C$229,$A35,Diario!$B$2:$B$229,">="&G$5,Diario!$B$2:$B$229,"<="&G$6,Diario!$H$2:$H$229,"<>REG") -> 0 | H35: =-SUMIFS(Diario!$K$2:$K$229,Diario!$C$2:$C$229,$A35,Diario!$B$2:$B$229,">="&H$5,Diario!$B$2:$B$229,"<="&H$6,Diario!$H$2:$H$229,"<>REG") -> -144.69
A36: 6710 | B36: Pérdidas procedentes del inmovilizado material | D36: =-SUMIFS(Diario!$K$2:$K$229,Diario!$C$2:$C$229,$A36,Diario!$B$2:$B$229,">="&D$5,Diario!$B$2:$B$229,"<="&D$6,Diario!$H$2:$H$229,"<>REG") -> 0 | E36: =-SUMIFS(Diario!$K$2:$K$229,Diario!$C$2:$C$229,$A36,Diario!$B$2:$B$229,">="&E$5,Diario!$B$2:$B$229,"<="&E$6,Diario!$H$2:$H$229,"<>REG") -> -3414.92 | F36: =-SUMIFS(Diario!$K$2:$K$229,Diario!$C$2:$C$229,$A36,Diario!$B$2:$B$229,">="&F$5,Diario!$B$2:$B$229,"<="&F$6,Diario!$H$2:$H$229,"<>REG") -> 0 | G36: =-SUMIFS(Diario!$K$2:$K$229,Diario!$C$2:$C$229,$A36,Diario!$B$2:$B$229,">="&G$5,Diario!$B$2:$B$229,"<="&G$6,Diario!$H$2:$H$229,"<>REG") -> 0 | H36: =-SUMIFS(Diario!$K$2:$K$229,Diario!$C$2:$C$229,$A36,Diario!$B$2:$B$229,">="&H$5,Diario!$B$2:$B$229,"<="&H$6,Diario!$H$2:$H$229,"<>REG") -> -3414.92
A37: 6780 | B37: Gastos excepcionales (sanciones...) | D37: =-SUMIFS(Diario!$K$2:$K$229,Diario!$C$2:$C$229,$A37,Diario!$B$2:$B$229,">="&D$5,Diario!$B$2:$B$229,"<="&D$6,Diario!$H$2:$H$229,"<>REG") -> 0 | E37: =-SUMIFS(Diario!$K$2:$K$229,Diario!$C$2:$C$229,$A37,Diario!$B$2:$B$229,">="&E$5,Diario!$B$2:$B$229,"<="&E$6,Diario!$H$2:$H$229,"<>REG") -> 0 | F37: =-SUMIFS(Diario!$K$2:$K$229,Diario!$C$2:$C$229,$A37,Diario!$B$2:$B$229,">="&F$5,Diario!$B$2:$B$229,"<="&F$6,Diario!$H$2:$H$229,"<>REG") -> -286.38 | G37: =-SUMIFS(Diario!$K$2:$K$229,Diario!$C$2:$C$229,$A37,Diario!$B$2:$B$229,">="&G$5,Diario!$B$2:$B$229,"<="&G$6,Diario!$H$2:$H$229,"<>REG") -> 0 | H37: =-SUMIFS(Diario!$K$2:$K$229,Diario!$C$2:$C$229,$A37,Diario!$B$2:$B$229,">="&H$5,Diario!$B$2:$B$229,"<="&H$6,Diario!$H$2:$H$229,"<>REG") -> -286.38
A38: 6810 | B38: Amortización del inmovilizado material | D38: =-SUMIFS(Diario!$K$2:$K$229,Diario!$C$2:$C$229,$A38,Diario!$B$2:$B$229,">="&D$5,Diario!$B$2:$B$229,"<="&D$6,Diario!$H$2:$H$229,"<>REG") -> -498.57 | E38: =-SUMIFS(Diario!$K$2:$K$229,Diario!$C$2:$C$229,$A38,Diario!$B$2:$B$229,">="&E$5,Diario!$B$2:$B$229,"<="&E$6,Diario!$H$2:$H$229,"<>REG") -> -720.29 | F38: =-SUMIFS(Diario!$K$2:$K$229,Diario!$C$2:$C$229,$A38,Diario!$B$2:$B$229,">="&F$5,Diario!$B$2:$B$229,"<="&F$6,Diario!$H$2:$H$229,"<>REG") -> -493.01 | G38: =-SUMIFS(Diario!$K$2:$K$229,Diario!$C$2:$C$229,$A38,Diario!$B$2:$B$229,">="&G$5,Diario!$B$2:$B$229,"<="&G$6,Diario!$H$2:$H$229,"<>REG") -> 0 | H38: =-SUMIFS(Diario!$K$2:$K$229,Diario!$C$2:$C$229,$A38,Diario!$B$2:$B$229,">="&H$5,Diario!$B$2:$B$229,"<="&H$6,Diario!$H$2:$H$229,"<>REG") -> -1711.87
A39: 7050 | B39: Prestaciones de servicios (alquileres) | D39: =-SUMIFS(Diario!$K$2:$K$229,Diario!$C$2:$C$229,$A39,Diario!$B$2:$B$229,">="&D$5,Diario!$B$2:$B$229,"<="&D$6,Diario!$H$2:$H$229,"<>REG") -> 0 | E39: =-SUMIFS(Diario!$K$2:$K$229,Diario!$C$2:$C$229,$A39,Diario!$B$2:$B$229,">="&E$5,Diario!$B$2:$B$229,"<="&E$6,Diario!$H$2:$H$229,"<>REG") -> 1737.73 | F39: =-SUMIFS(Diario!$K$2:$K$229,Diario!$C$2:$C$229,$A39,Diario!$B$2:$B$229,">="&F$5,Diario!$B$2:$B$229,"<="&F$6,Diario!$H$2:$H$229,"<>REG") -> 0 | G39: =-SUMIFS(Diario!$K$2:$K$229,Diario!$C$2:$C$229,$A39,Diario!$B$2:$B$229,">="&G$5,Diario!$B$2:$B$229,"<="&G$6,Diario!$H$2:$H$229,"<>REG") -> 0 | H39: =-SUMIFS(Diario!$K$2:$K$229,Diario!$C$2:$C$229,$A39,Diario!$B$2:$B$229,">="&H$5,Diario!$B$2:$B$229,"<="&H$6,Diario!$H$2:$H$229,"<>REG") -> 1737.73
B40: Total = Resultado del ejercicio | D40: =SUM(D30:D39) -> -2103.78 | E40: =SUM(E30:E39) -> -3276.45 | F40: =SUM(F30:F39) -> -2402.56 | G40: =SUM(G30:G39) -> 0 | H40: =SUM(H30:H39) -> -7782.79

Sheet Vehículos
A1: Inmovilizado: vehículos, amortización y rentabilidad
A2: Coste activado = precio + gastos necesarios para ponerlo a rodar (ITP, gestoría, aduana, matriculación). Amortización lineal por días.
A4: ID | B4: Vehículo | C4: Matrícula | D4: Estado | E4: Precio compra (€) | F4: ¿Precio estimado? | G4: % amort. anual | H4: Coste activado total (€) | I4: Amortización dotada (€) | J4: Valor neto contable (€) | K4: Ingresos (€) | L4: Gastos incl. amortización (€) | M4: Resultado del vehículo (€)
A5: V1 | B5: Nissan NV200 Furgon 1.5 dCi 90cv | C5: 1370KGF | D5: en_alquiler | E5: 3800 | F5: no | G5: 0.16 | H5: =SUMIFS(Diario!$F$2:$F$229,Diario!$I$2:$I$229,$A5,Diario!$C$2:$C$229,"218*",Diario!$B$2:$B$229,"<="&FechaCorte) -> 4197.04 | I5: =SUMIFS(Diario!$K$2:$K$229,Diario!$I$2:$I$229,$A5,Diario!$C$2:$C$229,"681*",Diario!$B$2:$B$229,"<="&FechaCorte) -> 382.31 | J5: =SUMIFS(Diario!$K$2:$K$229,Diario!$I$2:$I$229,$A5,Diario!$C$2:$C$229,"218*",Diario!$B$2:$B$229,"<="&FechaCorte)+SUMIFS(Diario!$K$2:$K$229,Diario!$I$2:$I$229,$A5,Diario!$C$2:$C$229,"281*",Diario!$B$2:$B$229,"<="&FechaCorte) -> 3814.73 | K5: =-SUMIFS(Diario!$K$2:$K$229,Diario!$I$2:$I$229,$A5,Diario!$C$2:$C$229,"7*",Diario!$H$2:$H$229,"<>REG",Diario!$B$2:$B$229,"<="&FechaCorte) -> 175.71 | L5: =SUMIFS(Diario!$K$2:$K$229,Diario!$I$2:$I$229,$A5,Diario!$C$2:$C$229,"6*",Diario!$H$2:$H$229,"<>REG",Diario!$B$2:$B$229,"<="&FechaCorte) -> 1449.43 | M5: =K5-L5 -> -1273.72
A6: V2 | B6: Nissan NV200 Furgon 1.5 dCi 90cv | C6: 2436KSS | D6: en_alquiler | E6: 9192 | F6: si | G6: 0.16 | H6: =SUMIFS(Diario!$F$2:$F$229,Diario!$I$2:$I$229,$A6,Diario!$C$2:$C$229,"218*",Diario!$B$2:$B$229,"<="&FechaCorte) -> 9192 | I6: =SUMIFS(Diario!$K$2:$K$229,Diario!$I$2:$I$229,$A6,Diario!$C$2:$C$229,"681*",Diario!$B$2:$B$229,"<="&FechaCorte) -> 1067.78 | J6: =SUMIFS(Diario!$K$2:$K$229,Diario!$I$2:$I$229,$A6,Diario!$C$2:$C$229,"218*",Diario!$B$2:$B$229,"<="&FechaCorte)+SUMIFS(Diario!$K$2:$K$229,Diario!$I$2:$I$229,$A6,Diario!$C$2:$C$229,"281*",Diario!$B$2:$B$229,"<="&FechaCorte) -> 8124.22 | K6: =-SUMIFS(Diario!$K$2:$K$229,Diario!$I$2:$I$229,$A6,Diario!$C$2:$C$229,"7*",Diario!$H$2:$H$229,"<>REG",Diario!$B$2:$B$229,"<="&FechaCorte) -> 983.51 | L6: =SUMIFS(Diario!$K$2:$K$229,Diario!$I$2:$I$229,$A6,Diario!$C$2:$C$229,"6*",Diario!$H$2:$H$229,"<>REG",Diario!$B$2:$B$229,"<="&FechaCorte) -> 2449.63 | M6: =K6-L6 -> -1466.12
A7: V3 | B7: Ford Fiesta | C7: 4161JHF | D7: vendido | E7: 5800 | F7: no | G7: 0.16 | H7: =SUMIFS(Diario!$F$2:$F$229,Diario!$I$2:$I$229,$A7,Diario!$C$2:$C$229,"218*",Diario!$B$2:$B$229,"<="&FechaCorte) -> 6156.7 | I7: =SUMIFS(Diario!$K$2:$K$229,Diario!$I$2:$I$229,$A7,Diario!$C$2:$C$229,"681*",Diario!$B$2:$B$229,"<="&FechaCorte) -> 261.78 | J7: =SUMIFS(Diario!$K$2:$K$229,Diario!$I$2:$I$229,$A7,Diario!$C$2:$C$229,"218*",Diario!$B$2:$B$229,"<="&FechaCorte)+SUMIFS(Diario!$K$2:$K$229,Diario!$I$2:$I$229,$A7,Diario!$C$2:$C$229,"281*",Diario!$B$2:$B$229,"<="&FechaCorte) -> 0 | K7: =-SUMIFS(Diario!$K$2:$K$229,Diario!$I$2:$I$229,$A7,Diario!$C$2:$C$229,"7*",Diario!$H$2:$H$229,"<>REG",Diario!$B$2:$B$229,"<="&FechaCorte) -> 0 | L7: =SUMIFS(Diario!$K$2:$K$229,Diario!$I$2:$I$229,$A7,Diario!$C$2:$C$229,"6*",Diario!$H$2:$H$229,"<>REG",Diario!$B$2:$B$229,"<="&FechaCorte) -> 3807.86 | M7: =K7-L7 -> -3807.86
A8: V4 | B8: Ford Mustang 2.3L (Blanco) | C8: P7559BDR (temporal) | D8: averiado_motor | E8: 6967.03 | F8: si | G8: 0.16 | H8: =SUMIFS(Diario!$F$2:$F$229,Diario!$I$2:$I$229,$A8,Diario!$C$2:$C$229,"218*",Diario!$B$2:$B$229,"<="&FechaCorte) -> 10475.76 | I8: =SUMIFS(Diario!$K$2:$K$229,Diario!$I$2:$I$229,$A8,Diario!$C$2:$C$229,"681*",Diario!$B$2:$B$229,"<="&FechaCorte) -> 0 | J8: =SUMIFS(Diario!$K$2:$K$229,Diario!$I$2:$I$229,$A8,Diario!$C$2:$C$229,"218*",Diario!$B$2:$B$229,"<="&FechaCorte)+SUMIFS(Diario!$K$2:$K$229,Diario!$I$2:$I$229,$A8,Diario!$C$2:$C$229,"281*",Diario!$B$2:$B$229,"<="&FechaCorte) -> 10475.76 | K8: =-SUMIFS(Diario!$K$2:$K$229,Diario!$I$2:$I$229,$A8,Diario!$C$2:$C$229,"7*",Diario!$H$2:$H$229,"<>REG",Diario!$B$2:$B$229,"<="&FechaCorte) -> 0 | L8: =SUMIFS(Diario!$K$2:$K$229,Diario!$I$2:$I$229,$A8,Diario!$C$2:$C$229,"6*",Diario!$H$2:$H$229,"<>REG",Diario!$B$2:$B$229,"<="&FechaCorte) -> 476.55 | M8: =K8-L8 -> -476.55
A9: V5 | B9: Ford Mustang (Gris) | C9: pendiente | D9: sin_matricular | E9: 7931.03 | F9: si | G9: 0.16 | H9: =SUMIFS(Diario!$F$2:$F$229,Diario!$I$2:$I$229,$A9,Diario!$C$2:$C$229,"218*",Diario!$B$2:$B$229,"<="&FechaCorte) -> 9926.13 | I9: =SUMIFS(Diario!$K$2:$K$229,Diario!$I$2:$I$229,$A9,Diario!$C$2:$C$229,"681*",Diario!$B$2:$B$229,"<="&FechaCorte) -> 0 | J9: =SUMIFS(Diario!$K$2:$K$229,Diario!$I$2:$I$229,$A9,Diario!$C$2:$C$229,"218*",Diario!$B$2:$B$229,"<="&FechaCorte)+SUMIFS(Diario!$K$2:$K$229,Diario!$I$2:$I$229,$A9,Diario!$C$2:$C$229,"281*",Diario!$B$2:$B$229,"<="&FechaCorte) -> 9926.13 | K9: =-SUMIFS(Diario!$K$2:$K$229,Diario!$I$2:$I$229,$A9,Diario!$C$2:$C$229,"7*",Diario!$H$2:$H$229,"<>REG",Diario!$B$2:$B$229,"<="&FechaCorte) -> 0 | L9: =SUMIFS(Diario!$K$2:$K$229,Diario!$I$2:$I$229,$A9,Diario!$C$2:$C$229,"6*",Diario!$H$2:$H$229,"<>REG",Diario!$B$2:$B$229,"<="&FechaCorte) -> 1233.38 | M9: =K9-L9 -> -1233.38
B10: TOTAL | E10: =SUM(E5:E9) -> 33690.06 | H10: =SUM(H5:H9) -> 39947.63 | I10: =SUM(I5:I9) -> 1711.87 | J10: =SUM(J5:J9) -> 32340.84 | K10: =SUM(K5:K9) -> 1159.22 | L10: =SUM(L5:L9) -> 9416.85 | M10: =SUM(M5:M9) -> -8257.63
B12: Gastos sin vehículo asignado (hosting, combustible sin identificar...) no aparecen aquí.
B13: El Ford Fiesta (V3) vendido: su «Gastos» incluye la pérdida contable de la venta.

Sheet IVA
A1: IVA por trimestre (para contrastar con el modelo 303 de Fisama)
A2: Estimación a partir de las facturas registradas. El IVA no deducible (facturas a nombre de otra persona, tickets) no cuenta como soportado.
A4: Trimestre | B4: Desde | C4: Hasta | D4: IVA repercutido (€) | E4: IVA soportado deducible (€) | F4: Diferencia del trimestre (€) | G4: Estado
A5: 2026-T1 | B5: 46023 | C5: 46112 | D5: =-SUMIFS(Diario!$K$2:$K$229,Diario!$C$2:$C$229,"477*",Diario!$B$2:$B$229,">="&B5,Diario!$B$2:$B$229,"<="&C5,Diario!$H$2:$H$229,"<>IVA") -> 0 | E5: =SUMIFS(Diario!$K$2:$K$229,Diario!$C$2:$C$229,"472*",Diario!$B$2:$B$229,">="&B5,Diario!$B$2:$B$229,"<="&C5,Diario!$H$2:$H$229,"<>IVA") -> 236.54 | F5: =D5-E5 -> -236.54 | G5: Cerrado. 236,54 € a compensar en trimestres siguientes
A6: 2026-T2 | B6: 46113 | C6: 46203 | D6: =-SUMIFS(Diario!$K$2:$K$229,Diario!$C$2:$C$229,"477*",Diario!$B$2:$B$229,">="&B6,Diario!$B$2:$B$229,"<="&C6,Diario!$H$2:$H$229,"<>IVA") -> 885.72 | E6: =SUMIFS(Diario!$K$2:$K$229,Diario!$C$2:$C$229,"472*",Diario!$B$2:$B$229,">="&B6,Diario!$B$2:$B$229,"<="&C6,Diario!$H$2:$H$229,"<>IVA") -> 371.69 | F6: =D6-E6 -> 514.03 | G6: Cerrado. Tras compensar 236,54 € de trimestres anteriores: 277,49 € A INGRESAR
A7: 2026-T3 | B7: 46204 | C7: 46295 | D7: =-SUMIFS(Diario!$K$2:$K$229,Diario!$C$2:$C$229,"477*",Diario!$B$2:$B$229,">="&B7,Diario!$B$2:$B$229,"<="&C7,Diario!$H$2:$H$229,"<>IVA") -> 0 | E7: =SUMIFS(Diario!$K$2:$K$229,Diario!$C$2:$C$229,"472*",Diario!$B$2:$B$229,">="&B7,Diario!$B$2:$B$229,"<="&C7,Diario!$H$2:$H$229,"<>IVA") -> 3312.31 | F7: =D7-E7 -> -3312.31 | G7: En curso
A8: 2026-T4 | B8: 46296 | C8: 46387 | D8: =-SUMIFS(Diario!$K$2:$K$229,Diario!$C$2:$C$229,"477*",Diario!$B$2:$B$229,">="&B8,Diario!$B$2:$B$229,"<="&C8,Diario!$H$2:$H$229,"<>IVA") -> 0 | E8: =SUMIFS(Diario!$K$2:$K$229,Diario!$C$2:$C$229,"472*",Diario!$B$2:$B$229,">="&B8,Diario!$B$2:$B$229,"<="&C8,Diario!$H$2:$H$229,"<>IVA") -> 0 | F8: =D8-E8 -> 0 | G8: -
A9: TOTAL | D9: =SUM(D5:D8) -> 885.72 | E9: =SUM(E5:E8) -> 3920.54 | F9: =SUM(F5:F8) -> -3034.82

Sheet Pendiente
A1: Qué falta o no cuadra
A2: Se genera solo cada vez que se actualizan los datos. Cuando nos paséis la información, el aviso desaparece.
A4: Prioridad | B4: Tema | C4: Detalle
A5: ALTA | B5: Cobros pendientes de confirmar | C5: Factura 9 Cielo Elizabeth Castillo Gomez (700,00 €): no sabemos si se ha cobrado. Figura como deuda del cliente.
A6: ALTA | B6: Cobros pendientes de confirmar | C6: Factura 10 David Chaves Jodar (700,00 €): no sabemos si se ha cobrado. Figura como deuda del cliente.
A7: ALTA | B7: Cobros pendientes de confirmar | C7: Factura 12 Cielo Elizabeth Castillo Gomez (490,05 €): no sabemos si se ha cobrado. Figura como deuda del cliente.
A8: ALTA | B8: Cobros pendientes de confirmar | C8: Factura 11 Adrian Diaz-Maroto Hernando (3.000,80 €): no sabemos si se ha cobrado. Figura como deuda del cliente.
A9: ALTA | B9: Cuadre bancario | C9: No tenemos ningún saldo real del BBVA de 2026. Sin extractos no se puede comprobar que la tesorería del balance sea la real.
A10: ALTA | B10: Partidas pendientes de aplicación | C10: Hay 24.498,06 € en la cuenta 555: pagos cuyo origen no sabemos (sobre todo compras de vehículos). Con los extractos del BBVA se reparten entre banco, deuda con socios o aportación.
A11: ALTA | B11: Vehículo V1 | C11: Nissan NV200 Furgon 1.5 dCi 90cv (3.800,00 €): no sabemos desde dónde se pagó (¿BBVA de la empresa? ¿un socio de su bolsillo?). Queda en 'partidas pendientes de aplicación'.
A12: ALTA | B12: Vehículo V3 | C12: Ford Fiesta (5.800,00 €): no sabemos desde dónde se pagó (¿BBVA de la empresa? ¿un socio de su bolsillo?). Queda en 'partidas pendientes de aplicación'.
A13: ALTA | B13: Vehículo V4 | C13: Ford Mustang 2.3L (Blanco): el precio de compra (6.967,03 €) es una ESTIMACIÓN (valor declarado en aduana). Falta la factura de compra real.
A14: ALTA | B14: Vehículo V4 | C14: Ford Mustang 2.3L (Blanco) (6.967,03 €): no sabemos desde dónde se pagó (¿BBVA de la empresa? ¿un socio de su bolsillo?). Queda en 'partidas pendientes de aplicación'.
A15: ALTA | B15: Vehículo V5 | C15: Ford Mustang (Gris): el precio de compra (7.931,03 €) es una ESTIMACIÓN (valor declarado en aduana). Falta la factura de compra real.
... A23: BAJA | B23: Factura emitida | C23: Factura 10 David Chaves Jodar: no sabemos a qué vehículo corresponde (afecta solo a la rentabilidad por vehículo).

Sheet Diario
A1: Asiento | B1: Fecha | C1: Cuenta | D1: Nombre de la cuenta | E1: Concepto | F1: Debe (€) | G1: Haber (€) | H1: Tipo | I1: Vehículo | J1: Documento | K1: Saldo D−H (€) | L1: Línea balance | M1: Línea PyG
A2: 1 | B2: 46022 | C2: 2130 | D2: Maquinaria | E2: Saldo de apertura: Maquinaria | F2: 9192 | H2: APE | J2: Balance 2025 Fisama | K2: =F2-G2 -> 9192 | L2: =INDEX('Plan de cuentas'!$C$5:$C$55,MATCH(C2,'Plan de cuentas'!$A$5:$A$55,0)) -> AII2 | M2: =INDEX('Plan de cuentas'!$D$5:$D$55,MATCH(C2,'Plan de cuentas'!$A$5:$A$55,0)) -> -
A3: 1 | B3: 46022 | C3: 5720 | D3: Bancos c/c BBVA | E3: Saldo de apertura: Bancos c/c BBVA ES73 0182 2458 1902 0130 3686 | F3: 66126.61 | H3: APE | J3: Balance 2025 Fisama | K3: =F3-G3 -> 66126.61 | L3: =INDEX('Plan de cuentas'!$C$5:$C$55,MATCH(C3,'Plan de cuentas'!$A$5:$A$55,0)) -> BVII | M3: =INDEX('Plan de cuentas'!$D$5:$D$55,MATCH(C3,'Plan de cuentas'!$A$5:$A$55,0)) -> -
A4: 1 | B4: 46022 | C4: 1000 | D4: Capital social | E4: Saldo de apertura: Capital social | G4: 3100 | H4: APE | J4: Balance 2025 Fisama | K4: =F4-G4 -> -3100 | L4: =INDEX('Plan de cuentas'!$C$5:$C$55,MATCH(C4,'Plan de cuentas'!$A$5:$A$55,0)) -> PAI | M4: =INDEX('Plan de cuentas'!$D$5:$D$55,MATCH(C4,'Plan de cuentas'!$A$5:$A$55,0)) -> -
A5: 1 | B5: 46022 | C5: 1180 | D5: Aportaciones de socios o propietarios | E5: Saldo de apertura: Aportaciones de socios o propietarios | G5: 72153.73 | H5: APE | J5: Balance 2025 Fisama | K5: =F5-G5 -> -72153.73 | L5: =INDEX('Plan de cuentas'!$C$5:$C$55,MATCH(C5,'Plan de cuentas'!$A$5:$A$55,0)) -> PAVI | M5: =INDEX('Plan de cuentas'!$D$5:$D$55,MATCH(C5,'Plan de cuentas'!$A$5:$A$55,0)) -> -
A6: 1 | B6: 46022 | C6: 1290 | D6: Resultado del ejercicio | E6: Saldo de apertura: Resultado del ejercicio 2025 | G6: 64.88 | H6: APE | J6: Balance 2025 Fisama | K6: =F6-G6 -> -64.88 | L6: =INDEX('Plan de cuentas'!$C$5:$C$55,MATCH(C6,'Plan de cuentas'!$A$5:$A$55,0)) -> PAVII | M6: =INDEX('Plan de cuentas'!$D$5:$D$55,MATCH(C6,'Plan de cuentas'!$A$5:$A$55,0)) -> -
A7: 2 | B7: 46023 | C7: 1290 | D7: Resultado del ejercicio | E7: Aplicacion del resultado 2025 | F7: 64.88 | H7: MAN | J7: M001 documentos/cuentas_anuales/2025_Cuenta-perdidas-y-ganancias-Fisama.pdf | K7: =F7-G7 -> 64.88 | L7: =INDEX('Plan de cuentas'!$C$5:$C$55,MATCH(C7,'Plan de cuentas'!$A$5:$A$55,0)) -> PAVII | M7: =INDEX('Plan de cuentas'!$D$5:$D$55,MATCH(C7,'Plan de cuentas'!$A$5:$A$55,0)) -> -
A8: 2 | B8: 46023 | C8: 1120 | D8: Reserva legal | E8: Aplicacion del resultado 2025 - reserva legal 10% | G8: 6.49 | H8: MAN | J8: M001 documentos/cuentas_anuales/2025_Cuenta-perdidas-y-ganancias-Fisama.pdf | K8: =F8-G8 -> -6.49 | L8: =INDEX('Plan de cuentas'!$C$5:$C$55,MATCH(C8,'Plan de cuentas'!$A$5:$A$55,0)) -> PAIII | M8: =INDEX('Plan de cuentas'!$D$5:$D$55,MATCH(C8,'Plan de cuentas'!$A$5:$A$55,0)) -> -
A9: 2 | B9: 46023 | C9: 1200 | D9: Remanente | E9: Aplicacion del resultado 2025 - remanente | G9: 58.39 | H9: MAN | J9: M001 documentos/cuentas_anuales/2025_Cuenta-perdidas-y-ganancias-Fisama.pdf | K9: =F9-G9 -> -58.39 | L9: =INDEX('Plan de cuentas'!$C$5:$C$55,MATCH(C9,'Plan de cuentas'!$A$5:$A$55,0)) -> PAV | M9: =INDEX('Plan de cuentas'!$D$5:$D$55,MATCH(C9,'Plan de cuentas'!$A$5:$A$55,0)) -> -
A10: 3 | B10: 46023 | C10: 2180 | D10: Elementos de transporte | E10: Reclasificacion NV200 2436KSS de Maquinaria (2130) a Elementos de transporte (2180) | F10: 9192 | H10: MAN | I10: V2 | J10: M002 documentos/cuentas_anuales/2025_Balance-situacion-Fisama.pdf | K10: =F10-G10 -> 9192 | L10: =INDEX('Plan de cuentas'!$C$5:$C$55,MATCH(C10,'Plan de cuentas'!$A$5:$A$55,0)) -> AII1 | M10: =INDEX('Plan de cuentas'!$D$5:$D$55,MATCH(C10,'Plan de cuentas'!$A$5:$A$55,0)) -> -
A11: 3 | B11: 46023 | C11: 2130 | D11: Maquinaria | E11: Reclasificacion NV200 2436KSS de Maquinaria (2130) a Elementos de transporte (2180) | G11: 9192 | H11: MAN | I11: V2 | J11: M002 documentos/cuentas_anuales/2025_Balance-situacion-Fisama.pdf | K11: =F11-G11 -> -9192 | L11: =INDEX('Plan de cuentas'!$C$5:$C$55,MATCH(C11,'Plan de cuentas'!$A$5:$A$55,0)) -> AII2 | M11: =INDEX('Plan de cuentas'!$D$5:$D$55,MATCH(C11,'Plan de cuentas'!$A$5:$A$55,0)) -> -
A12: 4 | B12: 46023 | C12: 6250 | D12: Primas de seguros | E12: Seguro terceros NV200 1370KGF (23/10/2025-23/10/2026) (Mutua Madrilena) | F12: 349.46 | H12: FRR | I12: V1 | J12: MUTUA-12692715 Mutua Madrilena | K12: =F12-G12 -> 349.46 | L12: =INDEX('Plan de cuentas'!$C$5:$C$55,MATCH(C12,'Plan de cuentas'!$A$5:$A$55,0)) -> PAVII | M12: =INDEX('Plan de cuentas'!$D$5:$D$55,MATCH(C12,'Plan de cuentas'!$A$5:$A$55,0)) -> P7a
A13: 4 | B13: 46023 | C13: 4100 | D13: Acreedores por prestaciones de servicios | E13: Seguro terceros NV200 1370KGF (23/10/2025-23/10/2026) (Mutua Madrilena) | G13: 349.46 | H13: FRR | I13: V1 | J13: MUTUA-12692715 Mutua Madrilena | K13: =F13-G13 -> -349.46 | L13: =INDEX('Plan de cuentas'!$C$5:$C$55,MATCH(C13,'Plan de cuentas'!$A$5:$A$55,0)) -> PCV1 | M13: =INDEX('Plan de cuentas'!$D$5:$D$55,MATCH(C13,'Plan de cuentas'!$A$5:$A$55,0)) -> -
A14: 5 | B14: 46023 | C14: 6250 | D14: Primas de seguros | E14: Seguro todo riesgo NV200 2436KSS (09/12/2025-23/10/2026) (Mutua Madrilena) | F14: 291.49 | H14: FRR | I14: V2 | J14: MUTUA-12692873 Mutua Madrilena | K14: =F14-G14 -> 291.49 | L14: =INDEX('Plan de cuentas'!$C$5:$C$55,MATCH(C14,'Plan de cuentas'!$A$5:$A$55,0)) -> PAVII | M14: =INDEX('Plan de cuentas'!$D$5:$D$55,MATCH(C14,'Plan de cuentas'!$A$5:$A$55,0)) -> P7a
A15: 5 | B15: 46023 | C15: 4100 | D15: Acreedores por prestaciones de servicios | E15: Seguro todo riesgo NV200 2436KSS (09/12/2025-23/10/2026) (Mutua Madrilena) | G15: 291.49 | H15: FRR | I15: V2 | J15: MUTUA-12692873 Mutua Madrilena | K15: =F15-G15 -> -291.49 | L15: =INDEX('Plan de cuentas'!$C$5:$C$55,MATCH(C15,'Plan de cuentas'!$A$5:$A$55,0)) -> PCV1 | M15: =INDEX('Plan de cuentas'!$D$5:$D$55,MATCH(C15,'Plan de cuentas'!$A$5:$A$55,0)) -> -
A16: 6 | B16: 46053 | C16: 6810 | D16: Amortización del inmovilizado material | E16: Amortización Nissan NV200 Furgon 1.5 dCi 90cv 2436KSS (31 días al 16% anual) | F16: 124.91 | H16: AMO | I16: V2 | J16: Amortización V2 01/2026 | K16: =F16-G16 -> 124.91 | L16: =INDEX('Plan de cuentas'!$C$5:$C$55,MATCH(C16,'Plan de cuentas'!$A$5:$A$55,0)) -> PAVII | M16: =INDEX('Plan de cuentas'!$D$5:$D$55,MATCH(C16,'Plan de cuentas'!$A$5:$A$55,0)) -> P8
A17: 6 | B17: 46053 | C17: 2818 | D17: Amortización acumulada de elementos de transporte | E17: Amortización Nissan NV200 Furgon 1.5 dCi 90cv 2436KSS (31 días al 16% anual) | G17: 124.91 | H17: AMO | I17: V2 | J17: Amortización V2 01/2026 | K17: =F17-G17 -> -124.91 | L17: =INDEX('Plan de cuentas'!$C$5:$C$55,MATCH(C17,'Plan de cuentas'!$A$5:$A$55,0)) -> AII3 | M17: =INDEX('Plan de cuentas'!$D$5:$D$55,MATCH(C17,'Plan de cuentas'!$A$5:$A$55,0)) -> -
A18: 7 | B18: 46080 | C18: 2180 | D18: Elementos de transporte | E18: Compra Nissan NV200 Furgon 1.5 dCi 90cv 1370KGF a Roberto de Roa (socio) | F18: 3800 | H18: COM | I18: V1 | J18: documentos/vehiculos/V1_1370KGF_2026-02-27_Contrato-compraventa-a-Roberto-de-Roa.pdf | K18: =F18-G18 -> 3800 | L18: =INDEX('Plan de cuentas'!$C$5:$C$55,MATCH(C18,'Plan de cuentas'!$A$5:$A$55,0)) -> AII1 | M18: =INDEX('Plan de cuentas'!$D$5:$D$55,MATCH(C18,'Plan de cuentas'!$A$5:$A$55,0)) -> -
A19: 7 | B19: 46080 | C19: 5550 | D19: Partidas pendientes de aplicación | E19: Compra Nissan NV200 Furgon 1.5 dCi 90cv 1370KGF a Roberto de Roa (socio) | G19: 3800 | H19: COM | I19: V1 | J19: documentos/vehiculos/V1_1370KGF_2026-02-27_Contrato-compraventa-a-Roberto-de-Roa.pdf | K19: =F19-G19 -> -3800 | L19: =INDEX('Plan de cuentas'!$C$5:$C$55,MATCH(C19,'Plan de cuentas'!$A$5:$A$55,0)) -> D555 | M19: =INDEX('Plan de cuentas'!$D$5:$D$55,MATCH(C19,'Plan de cuentas'!$A$5:$A$55,0)) -> -
A20: 8 | B20: 46081 | C20: 6810 | D20: Amortización del inmovilizado material | E20: Amortización Nissan NV200 Furgon 1.5 dCi 90cv 1370KGF (2 días al 16% anual) | F20: 3.33 | H20: AMO | I20: V1 | J20: Amortización V1 02/2026 | K20: =F20-G20 -> 3.33 | L20: =INDEX('Plan de cuentas'!$C$5:$C$55,MATCH(C20,'Plan de cuentas'!$A$5:$A$55,0)) -> PAVII | M20: =INDEX('Plan de cuentas'!$D$5:$D$55,MATCH(C20,'Plan de cuentas'!$A$5:$A$55,0)) -> P8
A21: 8 | B21: 46081 | C21: 2818 | D21: Amortización acumulada de elementos de transporte | E21: Amortización Nissan NV200 Furgon 1.5 dCi 90cv 1370KGF (2 días al 16% anual) | G21: 3.33 | H21: AMO | I21: V1 | J21: Amortización V1 02/2026 | K21: =F21-G21 -> -3.33 | L21: =INDEX('Plan de cuentas'!$C$5:$C$55,MATCH(C21,'Plan de cuentas'!$A$5:$A$55,0)) -> AII3 | M21: =INDEX('Plan de cuentas'!$D$5:$D$55,MATCH(C21,'Plan de cuentas'!$A$5:$A$55,0)) -> -
A22: 9 | B22: 46081 | C22: 6810 | D22: Amortización del inmovilizado material | E22: Amortización Nissan NV200 Furgon 1.5 dCi 90cv 2436KSS (28 días al 16% anual) | F22: 112.82 | H22: AMO | I22: V2 | J22: Amortización V2 02/2026 | K22: =F22-G22 -> 112.82 | L22: =INDEX('Plan de cuentas'!$C$5:$C$55,MATCH(C22,'Plan de cuentas'!$A$5:$A$55,0)) -> PAVII | M22: =INDEX('Plan de cuentas'!$D$5:$D$55,MATCH(C22,'Plan de cuentas'!$A$5:$A$55,0)) -> P8
A23: 9 | B23: 46081 | C23: 2818 | D23: Amortización acumulada de elementos de transporte | E23: Amortización Nissan NV200 Furgon 1.5 dCi 90cv 2436KSS (28 días al 16% anual) | G23: 112.82 | H23: AMO | I23: V2 | J23: Amortización V2 02/2026 | K23: =F23-G23 -> -112.82 | L23: =INDEX('Plan de cuentas'!$C$5:$C$55,MATCH(C23,'Plan de cuentas'!$A$5:$A$55,0)) -> AII3 | M23: =INDEX('Plan de cuentas'!$D$5:$D$55,MATCH(C23,'Plan de cuentas'!$A$5:$A$55,0)) -> -
A24: 10 | B24: 46084 | C24: 6220 | D24: Reparaciones y conservación | E24: Mantenimiento completo NV200 2436KSS: aceite filtros frenos 4 neumaticos alineacion (Taller Carlos Valin SL) | F24: 964.26 | H24: FRR | I24: V2 | J24: 71/2026 Taller Carlos Valin SL | K24: =F24-G24 -> 964.26 | L24: =INDEX('Plan de cuentas'!$C$5:$C$55,MATCH(C24,'Plan de cuentas'!$A$5:$A$55,0)) -> PAVII | M24: =INDEX('Plan de cuentas'!$D$5:$D$55,MATCH(C24,'Plan de cuentas'!$A$5:$A$55,0)) -> P7a
A25: 10 | B25: 46084 | C25: 4720 | D25: H.P. IVA soportado | E25: IVA soportado 71/2026 Taller Carlos Valin SL | F25: 202.52 | H25: FRR | I25: V2 | J25: 71/2026 Taller Carlos Valin SL | K25: =F25-G25 -> 202.52 | L25: =INDEX('Plan de cuentas'!$C$5:$C$55,MATCH(C25,'Plan de cuentas'!$A$5:$A$55,0)) -> BIII2 | M25: =INDEX('Plan de cuentas'!$D$5:$D$55,MATCH(C25,'Plan de cuentas'!$A$5:$A$55,0)) -> -
A26: 10 | B26: 46084 | C26: 4100 | D26: Acreedores por prestaciones de servicios | E26: Mantenimiento completo NV200 2436KSS: aceite filtros frenos 4 neumaticos alineacion (Taller Carlos Valin SL) | G26: 1166.78 | H26: FRR | I26: V2 | J26: 71/2026 Taller Carlos Valin SL | K26: =F26-G26 -> -1166.78 | L26: =INDEX('Plan de cuentas'!$C$5:$C$55,MATCH(C26,'Plan de cuentas'!$A$5:$A$55,0)) -> PCV1 | M26: =INDEX('Plan de cuentas'!$D$5:$D$55,MATCH(C26,'Plan de cuentas'!$A$5:$A$55,0)) -> -
A27: 11 | B27: 46085 | C27: 2180 | D27: Elementos de transporte | E27: Compra Ford Fiesta 4161JHF a Ruth Serrano | F27: 5800 | H27: COM | I27: V3 | J27: documentos/vehiculos/V3_4161JHF_2026-03-04_Contrato-compraventa-Ford-Fiesta.pdf | K27: =F27-G27 -> 5800 | L27: =INDEX('Plan de cuentas'!$C$5:$C$55,MATCH(C27,'Plan de cuentas'!$A$5:$A$55,0)) -> AII1 | M27: =INDEX('Plan de cuentas'!$D$5:$D$55,MATCH(C27,'Plan de cuentas'!$A$5:$A$55,0)) -> -
A28: 11 | B28: 46085 | C28: 5550 | D28: Partidas pendientes de aplicación | E28: Compra Ford Fiesta 4161JHF a Ruth Serrano | G28: 5800 | H28: COM | I28: V3 | J28: documentos/vehiculos/V3_4161JHF_2026-03-04_Contrato-compraventa-Ford-Fiesta.pdf | K28: =F28-G28 -> -5800 | L28: =INDEX('Plan de cuentas'!$C$5:$C$55,MATCH(C28,'Plan de cuentas'!$A$5:$A$55,0)) -> D555 | M28: =INDEX('Plan de cuentas'!$D$5:$D$55,MATCH(C28,'Plan de cuentas'!$A$5:$A$55,0)) -> -
A29: 12 | B29: 46085 | C29: 4100 | D29: Acreedores por prestaciones de servicios | E29: Pago 71/2026 Taller Carlos Valin SL | F29: 1166.78 | H29: PAG | I29: V2 | J29: 71/2026 Taller Carlos Valin SL | K29: =F29-G29 -> 1166.78 | L29: =INDEX('Plan de cuentas'!$C$5:$C$55,MATCH(C29,'Plan de cuentas'!$A$5:$A$55,0)) -> PCV1 | M29: =INDEX('Plan de cuentas'!$D$5:$D$55,MATCH(C29,'Plan de cuentas'!$A$5:$A$55,0)) -> -
A30: 12 | B30: 46085 | C30: 5720 | D30: Bancos c/c BBVA | E30: Pago 71/2026 Taller Carlos Valin SL | G30: 1166.78 | H30: PAG | I30: V2 | J30: 71/2026 Taller Carlos Valin SL | K30: =F30-G30 -> -1166.78 | L30: =INDEX('Plan de cuentas'!$C$5:$C$55,MATCH(C30,'Plan de cuentas'!$A$5:$A$55,0)) -> BVII | M30: =INDEX('Plan de cuentas'!$D$5:$D$55,MATCH(C30,'Plan de cuentas'!$A$5:$A$55,0)) -> -
A31: 13 | B31: 46108 | C31: 2180 | D31: Elementos de transporte | E31: Cambio titularidad Ford Fiesta 4161JHF (suplidos: ITP 232.00 + tasa DGT 55.70 + varios 15.00) (Gestoria Amengual (Miguel Mas Amengual)) | F31: 54 | H31: FRR | I31: V3 | J31: 26A900069 Gestoria Amengual (Miguel Mas Amengual) | K31: =F31-G31 -> 54 | L31: =INDEX('Plan de cuentas'!$C$5:$C$55,MATCH(C31,'Plan de cuentas'!$A$5:$A$55,0)) -> AII1 | M31: =INDEX('Plan de cuentas'!$D$5:$D$55,MATCH(C31,'Plan de cuentas'!$A$5:$A$55,0)) -> -
A32: 13 | B32: 46108 | C32: 4720 | D32: H.P. IVA soportado | E32: IVA soportado 26A900069 Gestoria Amengual (Miguel Mas Amengual) | F32: 11.34 | H32: FRR | I32: V3 | J32: 26A900069 Gestoria Amengual (Miguel Mas Amengual) | K32: =F32-G32 -> 11.34 | L32: =INDEX('Plan de cuentas'!$C$5:$C$55,MATCH(C32,'Plan de cuentas'!$A$5:$A$55,0)) -> BIII2 | M32: =INDEX('Plan de cuentas'!$D$5:$D$55,MATCH(C32,'Plan de cuentas'!$A$5:$A$55,0)) -> -
A33: 13 | B33: 46108 | C33: 2180 | D33: Elementos de transporte | E33: Suplidos: Cambio titularidad Ford Fiesta 4161JHF (suplidos: ITP 232.00 + tasa DGT 55.70 + varios 15.00) (Gestoria Amengual (Miguel Mas Amengual)) | F33: 302.7 | H33: FRR | I33: V3 | J33: 26A900069 Gestoria Amengual (Miguel Mas Amengual) | K33: =F33-G33 -> 302.7 | L33: =INDEX('Plan de cuentas'!$C$5:$C$55,MATCH(C33,'Plan de cuentas'!$A$5:$A$55,0)) -> AII1 | M33: =INDEX('Plan de cuentas'!$D$5:$D$55,MATCH(C33,'Plan de cuentas'!$A$5:$A$55,0)) -> -
A34: 13 | B34: 46108 | C34: 4100 | D34: Acreedores por prestaciones de servicios | E34: Cambio titularidad Ford Fiesta 4161JHF (suplidos: ITP 232.00 + tasa DGT 55.70 + varios 15.00) (Gestoria Amengual (Miguel Mas Amengual)) | G34: 368.04 | H34: FRR | I34: V3 | J34: 26A900069 Gestoria Amengual (Miguel Mas Amengual) | K34: =F34-G34 -> -368.04 | L34: =INDEX('Plan de cuentas'!$C$5:$C$55,MATCH(C34,'Plan de cuentas'!$A$5:$A$55,0)) -> PCV1 | M34: =INDEX('Plan de cuentas'!$D$5:$D$55,MATCH(C34,'Plan de cuentas'!$A$5:$A$55,0)) -> -
A35: 14 | B35: 46108 | C35: 2180 | D35: Elementos de transporte | E35: Cambio titularidad NV200 1370KGF - expediente a nombre de Roberto de Roa (Gestoria Amengual (Miguel Mas Amengual)) | F35: 54 | H35: FRR | I35: V1 | J35: 26A900070 Gestoria Amengual (Miguel Mas Amengual) | K35: =F35-G35 -> 54 | L35: =INDEX('Plan de cuentas'!$C$5:$C$55,MATCH(C35,'Plan de cuentas'!$A$5:$A$55,0)) -> AII1 | M35: =INDEX('Plan de cuentas'!$D$5:$D$55,MATCH(C35,'Plan de cuentas'!$A$5:$A$55,0)) -> -
A36: 14 | B36: 46108 | C36: 4720 | D36: H.P. IVA soportado | E36: IVA soportado 26A900070 Gestoria Amengual (Miguel Mas Amengual) | F36: 11.34 | H36: FRR | I36: V1 | J36: 26A900070 Gestoria Amengual (Miguel Mas Amengual) | K36: =F36-G36 -> 11.34 | L36: =INDEX('Plan de cuentas'!$C$5:$C$55,MATCH(C36,'Plan de cuentas'!$A$5:$A$55,0)) -> BIII2 | M36: =INDEX('Plan de cuentas'!$D$5:$D$55,MATCH(C36,'Plan de cuentas'!$A$5:$A$55,0)) -> -
A37: 14 | B37: 46108 | C37: 2180 | D37: Elementos de transporte | E37: Suplidos: Cambio titularidad NV200 1370KGF - expediente a nombre de Roberto de Roa (Gestoria Amengual (Miguel Mas Amengual)) | F37: 65.7 | H37: FRR | I37: V1 | J37: 26A900070 Gestoria Amengual (Miguel Mas Amengual) | K37: =F37-G37 -> 65.7 | L37: =INDEX('Plan de cuentas'!$C$5:$C$55,MATCH(C37,'Plan de cuentas'!$A$5:$A$55,0)) -> AII1 | M37: =INDEX('Plan de cuentas'!$D$5:$D$55,MATCH(C37,'Plan de cuentas'!$A$5:$A$55,0)) -> -
A38: 14 | B38: 46108 | C38: 4100 | D38: Acreedores por prestaciones de servicios | E38: Cambio titularidad NV200 1370KGF - expediente a nombre de Roberto de Roa (Gestoria Amengual (Miguel Mas Amengual)) | G38: 131.04 | H38: FRR | I38: V1 | J38: 26A900070 Gestoria Amengual (Miguel Mas Amengual) | K38: =F38-G38 -> -131.04 | L38: =INDEX('Plan de cuentas'!$C$5:$C$55,MATCH(C38,'Plan de cuentas'!$A$5:$A$55,0)) -> PCV1 | M38: =INDEX('Plan de cuentas'!$D$5:$D$55,MATCH(C38,'Plan de cuentas'!$A$5:$A$55,0)) -> -
A39: 15 | B39: 46108 | C39: 2180 | D39: Elementos de transporte | E39: Cambio titularidad NV200 1370KGF (suplidos: ITP 152.64 + tasas) (Gestoria Amengual (Miguel Mas Amengual)) | F39: 54 | H39: FRR | I39: V1 | J39: 26A900071 Gestoria Amengual (Miguel Mas Amengual) | K39: =F39-G39 -> 54 | L39: =INDEX('Plan de cuentas'!$C$5:$C$55,MATCH(C39,'Plan de cuentas'!$A$5:$A$55,0)) -> AII1 | M39: =INDEX('Plan de cuentas'!$D$5:$D$55,MATCH(C39,'Plan de cuentas'!$A$5:$A$55,0)) -> -
A40: 15 | B40: 46108 | C40: 4720 | D40: H.P. IVA soportado | E40: IVA soportado 26A900071 Gestoria Amengual (Miguel Mas Amengual) | F40: 11.34 | H40: FRR | I40: V1 | J40: 26A900071 Gestoria Amengual (Miguel Mas Amengual) | K40: =F40-G40 -> 11.34 | L40: =INDEX('Plan de cuentas'!$C$5:$C$55,MATCH(C40,'Plan de cuentas'!$A$5:$A$55,0)) -> BIII2 | M40: =INDEX('Plan de cuentas'!$D$5:$D$55,MATCH(C40,'Plan de cuentas'!$A$5:$A$55,0)) -> -
...

Sheet Sumas y saldos
A1: Balance de sumas y saldos
A2: Movimientos acumulados de cada cuenta hasta la fecha de corte.
